2023-02-26 21:59:16,584 DEBUG    root            Loaded Command Group: ['gcloud', 'auth']
2023-02-26 21:59:16,588 DEBUG    root            Loaded Command Group: ['gcloud', 'auth', 'list']
2023-02-26 21:59:16,591 DEBUG    root            Running [gcloud.auth.list] with arguments: [--filter: "status=ACTIVE", --format: "value(account)", --quiet: "True", --verbosity: "warning"]
2023-02-26 21:59:17,199 DEBUG    root            Chosen display Format:    table[title='Credentialed Accounts'](
        status.yesno(yes='*', no=''):label=ACTIVE,
        account
    ) value(account)
2023-02-26 21:59:17,204 INFO     root            Display format: "    table[title='Credentialed Accounts'](
        status.yesno(yes='*', no=''):label=ACTIVE,
        account
    ) value(account)"
2023-02-26 21:59:17,204 INFO     ___FILE_ONLY___ wongshennan@gmail.com

2023-02-26 21:59:17,205 DEBUG    root            Checking for updates...
2023-02-26 21:59:17,215 DEBUG    urllib3.connectionpool Starting new HTTPS connection (1): dl.google.com:443
2023-02-26 21:59:19,342 DEBUG    urllib3.connectionpool https://dl.google.com:443 "GET /dl/cloudsdk/channels/rapid/components-2.json HTTP/1.1" 200 206156
2023-02-26 21:59:32,965 DEBUG    root            Failed to perform update check.
Traceback (most recent call last):
  File "/Users/wongshennan/Library/Application Support/cloud-code/installer/google-cloud-sdk/lib/third_party/urllib3/response.py", line 441, in _error_catcher
    yield
  File "/Users/wongshennan/Library/Application Support/cloud-code/installer/google-cloud-sdk/lib/third_party/urllib3/response.py", line 522, in read
    data = self._fp.read(amt) if not fp_closed else b""
  File "/Users/wongshennan/opt/anaconda3/lib/python3.9/http/client.py", line 463, in read
    n = self.readinto(b)
  File "/Users/wongshennan/opt/anaconda3/lib/python3.9/http/client.py", line 507, in readinto
    n = self.fp.readinto(b)
  File "/Users/wongshennan/opt/anaconda3/lib/python3.9/socket.py", line 704, in readinto
    return self._sock.recv_into(b)
  File "/Users/wongshennan/opt/anaconda3/lib/python3.9/ssl.py", line 1242, in recv_into
    return self.read(nbytes, buffer)
  File "/Users/wongshennan/opt/anaconda3/lib/python3.9/ssl.py", line 1100, in read
    return self._sslobj.read(len, buffer)
socket.timeout: The read operation timed out

During handling of the above exception, another exception occurred:

Traceback (most recent call last):
  File "/Users/wongshennan/Library/Application Support/cloud-code/installer/google-cloud-sdk/lib/third_party/requests/models.py", line 753, in generate
    for chunk in self.raw.stream(chunk_size, decode_content=True):
  File "/Users/wongshennan/Library/Application Support/cloud-code/installer/google-cloud-sdk/lib/third_party/urllib3/response.py", line 579, in stream
    data = self.read(amt=amt, decode_content=decode_content)
  File "/Users/wongshennan/Library/Application Support/cloud-code/installer/google-cloud-sdk/lib/third_party/urllib3/response.py", line 544, in read
    raise IncompleteRead(self._fp_bytes_read, self.length_remaining)
  File "/Users/wongshennan/opt/anaconda3/lib/python3.9/contextlib.py", line 137, in __exit__
    self.gen.throw(typ, value, traceback)
  File "/Users/wongshennan/Library/Application Support/cloud-code/installer/google-cloud-sdk/lib/third_party/urllib3/response.py", line 446, in _error_catcher
    raise ReadTimeoutError(self._pool, None, "Read timed out.")
urllib3.exceptions.ReadTimeoutError: HTTPSConnectionPool(host='dl.google.com', port=443): Read timed out.

During handling of the above exception, another exception occurred:

Traceback (most recent call last):
  File "/Users/wongshennan/Library/Application Support/cloud-code/installer/google-cloud-sdk/lib/googlecloudsdk/gcloud_main.py", line 61, in UpdateCheck
    update_manager.UpdateManager.PerformUpdateCheck(command_path=command_path)
  File "/Users/wongshennan/Library/Application Support/cloud-code/installer/google-cloud-sdk/lib/googlecloudsdk/core/updater/update_manager.py", line 304, in PerformUpdateCheck
    manager._PerformUpdateCheck(command_path, force=force)
  File "/Users/wongshennan/Library/Application Support/cloud-code/installer/google-cloud-sdk/lib/googlecloudsdk/core/updater/update_manager.py", line 738, in _PerformUpdateCheck
    (_, diff) = self._GetStateAndDiff(
  File "/Users/wongshennan/Library/Application Support/cloud-code/installer/google-cloud-sdk/lib/googlecloudsdk/core/updater/update_manager.py", line 692, in _GetStateAndDiff
    latest_snapshot = self._GetLatestSnapshot(version=version,
  File "/Users/wongshennan/Library/Application Support/cloud-code/installer/google-cloud-sdk/lib/googlecloudsdk/core/updater/update_manager.py", line 675, in _GetLatestSnapshot
    return snapshots.ComponentSnapshot.FromURLs(
  File "/Users/wongshennan/Library/Application Support/cloud-code/installer/google-cloud-sdk/lib/googlecloudsdk/core/updater/snapshots.py", line 175, in FromURLs
    data = [
  File "/Users/wongshennan/Library/Application Support/cloud-code/installer/google-cloud-sdk/lib/googlecloudsdk/core/updater/snapshots.py", line 176, in <listcomp>
    (ComponentSnapshot._DictFromURL(
  File "/Users/wongshennan/Library/Application Support/cloud-code/installer/google-cloud-sdk/lib/googlecloudsdk/core/updater/snapshots.py", line 200, in _DictFromURL
    response = installers.MakeRequest(url, command_path)
  File "/Users/wongshennan/Library/Application Support/cloud-code/installer/google-cloud-sdk/lib/googlecloudsdk/core/updater/installers.py", line 114, in MakeRequest
    return _RawRequest(url, headers=headers, timeout=timeout)
  File "/Users/wongshennan/Library/Application Support/cloud-code/installer/google-cloud-sdk/lib/googlecloudsdk/core/updater/installers.py", line 162, in _RawRequest
    return retryer.RetryOnException(
  File "/Users/wongshennan/Library/Application Support/cloud-code/installer/google-cloud-sdk/lib/googlecloudsdk/core/util/retry.py", line 201, in RetryOnException
    exceptions.reraise(exc_info[1], tb=exc_info[2])
  File "/Users/wongshennan/Library/Application Support/cloud-code/installer/google-cloud-sdk/lib/googlecloudsdk/core/exceptions.py", line 146, in reraise
    six.reraise(type(exc_value), exc_value, tb)
  File "/Users/wongshennan/Library/Application Support/cloud-code/installer/google-cloud-sdk/lib/third_party/six/__init__.py", line 719, in reraise
    raise value
  File "/Users/wongshennan/Library/Application Support/cloud-code/installer/google-cloud-sdk/lib/googlecloudsdk/core/util/retry.py", line 182, in TryFunc
    return func(*args, **kwargs), None
  File "/Users/wongshennan/Library/Application Support/cloud-code/installer/google-cloud-sdk/lib/googlecloudsdk/core/updater/installers.py", line 192, in _ExecuteRequestAndRaiseExceptions
    response = requests_session.get(
  File "/Users/wongshennan/Library/Application Support/cloud-code/installer/google-cloud-sdk/lib/third_party/requests/sessions.py", line 555, in get
    return self.request('GET', url, **kwargs)
  File "/Users/wongshennan/Library/Application Support/cloud-code/installer/google-cloud-sdk/lib/googlecloudsdk/core/transport.py", line 272, in WrappedRequest
    handler_response = self.response_class.FromResponse(response)
  File "/Users/wongshennan/Library/Application Support/cloud-code/installer/google-cloud-sdk/lib/googlecloudsdk/core/requests.py", line 382, in FromResponse
    return cls(response.status_code, response.headers, response.content)
  File "/Users/wongshennan/Library/Application Support/cloud-code/installer/google-cloud-sdk/lib/third_party/requests/models.py", line 831, in content
    self._content = b''.join(self.iter_content(CONTENT_CHUNK_SIZE)) or b''
  File "/Users/wongshennan/Library/Application Support/cloud-code/installer/google-cloud-sdk/lib/third_party/requests/models.py", line 760, in generate
    raise ConnectionError(e)
requests.exceptions.ConnectionError: HTTPSConnectionPool(host='dl.google.com', port=443): Read timed out.
